<?xml version="1.0" encoding="utf-8"?>
<!-- This URDF was automatically created by SolidWorks to URDF Exporter! Originally created by Stephen Brawner (brawner@gmail.com) 
     Commit Version: 1.6.0-4-g7f85cfe  Build Version: 1.6.7995.38578
     For more information, please see http://wiki.ros.org/sw_urdf_exporter -->
<robot
  name="R7-900_description">
  <link
    name="base_link">
    <inertial>
      <origin
        xyz="-0.040413 -3.6248E-05 0.092724"
        rpy="0 0 0" />
      <mass
        value="9.3967" />
      <inertia
        ixx="0.054482"
        ixy="-0.00012575"
        ixz="-0.0033739"
        iyy="0.087595"
        iyz="-9.5456E-06"
        izz="0.084152" />
    </inertial>
    <visual>
      <origin
        xyz="0 0 0"
        rpy="0 0 0" />
      <geometry>
        <mesh
          filename="package://QJ7-900_stl/meshes/base_link.STL" />
      </geometry>
      <material
        name="">
        <color
          rgba="0.79216 0.81961 0.93333 1" />
      </material>
    </visual>
    <collision>
      <origin
        xyz="0 0 0"
        rpy="0 0 0" />
      <geometry>
        <mesh
          filename="package://QJ7-900_stl/meshes/base_link.STL" />
      </geometry>
    </collision>
  </link>

  <link
    name="link_1">
    <inertial>
      <origin
        xyz="0.015148 -0.0035955 0.090973"
        rpy="0 0 0" />
      <mass
        value="6.0875" />
      <inertia
        ixx="0.040605"
        ixy="0.00058873"
        ixz="-0.0077766"
        iyy="0.046881"
        iyz="0.0011242"
        izz="0.032179" />
    </inertial>
    <visual>
      <origin
        xyz="0 0 0"
        rpy="0 0 0" />
      <geometry>
        <mesh
          filename="package://QJ7-900_stl/meshes/link_1.STL" />
      </geometry>
      <material
        name="">
        <color
          rgba="1 1 1 1" />
      </material>
    </visual>
    <collision>
      <origin
        xyz="0 0 0"
        rpy="0 0 0" />
      <geometry>
        <mesh
          filename="package://QJ7-900_stl/meshes/link_1.STL" />
      </geometry>
    </collision>
  </link>
  
  <joint
    name="joint_1"
    type="revolute">
    <origin
      xyz="0 0 0.2015"
      rpy="0 0 0" />
    <parent
      link="base_link" />
    <child
      link="link_1" />
    <axis
      xyz="0 0 -1" />
    <limit
      lower="-3"
      upper="3"
      effort="100"
      velocity="3" />
  </joint>
  <link
    name="link_2">
    <inertial>
      <origin
        xyz="0.0061742 0.15315 0.038744"
        rpy="0 0 0" />
      <mass
        value="4.1869" />
      <inertia
        ixx="0.15454"
        ixy="-0.00049253"
        ixz="0.0002854"
        iyy="0.039229"
        iyz="-0.00030574"
        izz="0.12528" />
    </inertial>
    <visual>
      <origin
        xyz="0 0 0"
        rpy="0 0 0" />
      <geometry>
        <mesh
          filename="package://QJ7-900_stl/meshes/link_2.STL" />
      </geometry>
      <material
        name="">
        <color
          rgba="0.79216 0.81961 0.93333 1" />
      </material>
    </visual>
    <collision>
      <origin
        xyz="0 0 0"
        rpy="0 0 0" />
      <geometry>
        <mesh
          filename="package://QJ7-900_stl/meshes/link_2.STL" />
      </geometry>
    </collision>
  </link>
  <joint
    name="joint_2"
    type="revolute">
    <origin
      xyz="0.05 0.041 0.162"
      rpy="1.5708 0 0" />
    <parent
      link="link_1" />
    <child
      link="link_2" />
    <axis
      xyz="0 0 -1" />
    <limit
      lower="-3"
      upper="3"
      effort="100"
      velocity="3" />
  </joint>
  <link
    name="link_3">
    <inertial>
      <origin
        xyz="0.038554 -0.043544 0.052978"
        rpy="0 0 0" />
      <mass
        value="5.2733" />
      <inertia
        ixx="0.054795"
        ixy="0.0051339"
        ixz="0.00075606"
        iyy="0.015457"
        iyz="-0.00092549"
        izz="0.057401" />
    </inertial>
    <visual>
      <origin
        xyz="0 0 0"
        rpy="0 0 0" />
      <geometry>
        <mesh
          filename="package://QJ7-900_stl/meshes/link_3.STL" />
      </geometry>
      <material
        name="">
        <color
          rgba="1 1 1 1" />
      </material>
    </visual>
    <collision>
      <origin
        xyz="0 0 0"
        rpy="0 0 0" />
      <geometry>
        <mesh
          filename="package://QJ7-900_stl/meshes/link_3.STL" />
      </geometry>
    </collision>
  </link>
  <joint
    name="joint_3"
    type="revolute">
    <origin
      xyz="0 0.42 -0.008"
      rpy="0 0 1.5708" />
    <parent
      link="link_2" />
    <child
      link="link_3" />
    <axis
      xyz="0 0 -1" />
    <limit
      lower="-3"
      upper="3"
      effort="100"
      velocity="3" />
  </joint>
  <link
    name="link_4">
    <inertial>
      <origin
        xyz="-0.00029498 -0.0013119 0.090128"
        rpy="0 0 0" />
      <mass
        value="2.2276" />
      <inertia
        ixx="0.012856"
        ixy="5.5068E-07"
        ixz="-3.9033E-05"
        iyy="0.010225"
        iyz="0.00032748"
        izz="0.0062976" />
    </inertial>
    <visual>
      <origin
        xyz="0 0 0"
        rpy="0 0 0" />
      <geometry>
        <mesh
          filename="package://QJ7-900_stl/meshes/link_4.STL" />
      </geometry>
      <material
        name="">
        <color
          rgba="0.79216 0.81961 0.93333 1" />
      </material>
    </visual>
    <collision>
      <origin
        xyz="0 0 0"
        rpy="0 0 0" />
      <geometry>
        <mesh
          filename="package://QJ7-900_stl/meshes/link_4.STL" />
      </geometry>
    </collision>
  </link>
  <joint
    name="joint_4"
    type="revolute">
    <origin
      xyz="0.055 -0.244 0.049"
      rpy="1.5708 0 0" />
    <parent
      link="link_3" />
    <child
      link="link_4" />
    <axis
      xyz="0 0 1" />
    <limit
      lower="-3"
      upper="3"
      effort="100"
      velocity="3" />
  </joint>
  <link
    name="link_5">
    <inertial>
      <origin
        xyz="0.0030646 -0.012914 0.03783"
        rpy="0 0 0" />
      <mass
        value="0.79838" />
      <inertia
        ixx="0.0015898"
        ixy="-5.4489E-05"
        ixz="2.0444E-05"
        iyy="0.00079629"
        iyz="-3.4472E-05"
        izz="0.001549" />
    </inertial>
    <visual>
      <origin
        xyz="0 0 0"
        rpy="0 0 0" />
      <geometry>
        <mesh
          filename="package://QJ7-900_stl/meshes/link_5.STL" />
      </geometry>
      <material
        name="">
        <color
          rgba="0.79216 0.81961 0.93333 1" />
      </material>
    </visual>
    <collision>
      <origin
        xyz="0 0 0"
        rpy="0 0 0" />
      <geometry>
        <mesh
          filename="package://QJ7-900_stl/meshes/link_5.STL" />
      </geometry>
    </collision>
  </link>
  <joint
    name="joint_5"
    type="revolute">
    <origin
      xyz="0 -0.033 0.186"
      rpy="-1.5518 0 0" />
    <parent
      link="link_4" />
    <child
      link="link_5" />
    <axis
      xyz="0 -0.018946 -0.99982" />
    <limit
      lower="-3"
      upper="3"
      effort="100"
      velocity="3" />
  </joint>
  <link
    name="link_6">
    <inertial>
      <origin
        xyz="6.1991E-05 -4.8508E-10 0.0054511"
        rpy="0 0 0" />
      <mass
        value="0.050698" />
      <inertia
        ixx="1.9067E-05"
        ixy="-8.0934E-14"
        ixz="-2.2326E-09"
        iyy="1.9041E-05"
        iyz="2.6839E-14"
        izz="3.6864E-05" />
    </inertial>
    <visual>
      <origin
        xyz="0 0 0"
        rpy="0 0 0" />
      <geometry>
        <mesh
          filename="package://QJ7-900_stl/meshes/link_6.STL" />
      </geometry>
      <material
        name="">
        <color
          rgba="0.79216 0.81961 0.93333 1" />
      </material>
    </visual>
    <collision>
      <origin
        xyz="0 0 0"
        rpy="0 0 0" />
      <geometry>
        <mesh
          filename="package://QJ7-900_stl/meshes/link_6.STL" />
      </geometry>
    </collision>
  </link>
  <joint
    name="joint_6"
    type="revolute">
    <origin
      xyz="3.7006E-05 -0.08286 0.034576"
      rpy="1.5518 0 0" />
    <parent
      link="link_5" />
    <child
      link="link_6" />
    <axis
      xyz="0 0 1" />
    <limit
      lower="-3"
      upper="3"
      effort="100"
      velocity="3" />
  </joint>
</robot>